<?xml version="1.0" encoding="utf-8"?>
<mujoco model="simple_wheeled_robot">
  <!-- Настройки -->
  <option timestep="0.0001" integrator="RK4" cone="elliptic"/>
  <option gravity="0 0 -9.81"/>

  <!-- Статистика -->
  <statistic center="0 0 0.5" extent="2"/>

  <!-- Мир -->
  <worldbody>
    <!-- Пол -->
    <light name="top" pos="0 0 3" dir="0 0 -1" directional="true"/>
    <geom name="floor" type="plane" size="10 10 0.1" rgba="0.8 0.9 0.8 1" friction="1 0.005 0.0001"/>

    <!-- Основной корпус робота -->
    <body name="torso" pos="0 0 0.5">
      <freejoint name="root"/>
      <geom name="torso_geom" type="box" size="0.1 0.07 0.05" mass="0.7" rgba="0.2 0.6 1 1"/>

      <!-- Левое колесо - прикреплено к ЦЕНТРУ корпуса -->
      <body name="left_wheel" pos="0 0 -0.05">  <!-- Z=-0.05 (ниже центра корпуса) -->
        <joint name="left_wheel_joint" type="hinge" axis="0 1 0" pos="0 0 0" limited="false"/>
        <geom name="left_wheel_geom" type="cylinder" size="0.1 0.01"
              euler="90 0 0" mass="0.3" rgba="0.3 0.3 0.3 1" pos="0 0.1 0"/> <!-- Y=0.1 (смещено влево) -->
      </body>

      <!-- Правое колесо - прикреплено к ЦЕНТРУ корпуса -->
      <body name="right_wheel" pos="0 0 -0.05">  <!-- Z=-0.05 (ниже центра корпуса) -->
        <joint name="right_wheel_joint" type="hinge" axis="0 1 0" pos="0 0 0" limited="false"/>
        <geom name="right_wheel_geom" type="cylinder" size="0.1 0.01"
              euler="90 0 0" mass="0.3" rgba="0.3 0.3 0.3 1" pos="0 -0.1 0"/> <!-- Y=-0.1 (смещено вправо) -->
      </body>
    </body>
  </worldbody>

  <!-- Приводы -->
  <actuator>
    <!-- Двигатели колес -->
    <motor name="left_wheel_motor" joint="left_wheel_joint" gear="50" ctrllimited="true" ctrlrange="-100 100"/>
    <motor name="right_wheel_motor" joint="right_wheel_joint" gear="50" ctrllimited="true" ctrlrange="-100 100"/>
  </actuator>

  <!-- Датчики -->
  <sensor>
    <!-- Позиция и ориентация корпуса -->
    <framepos name="torso_pos" objtype="body" objname="torso"/>
    <framequat name="torso_quat" objtype="body" objname="torso"/>

    <!-- Скорость колес -->
    <jointvel name="left_wheel_vel" joint="left_wheel_joint"/>
    <jointvel name="right_wheel_vel" joint="right_wheel_joint"/>
  </sensor>
</mujoco>